<mujoco model="7dof_robot">
    <compiler angle="radian"/>
    <option timestep="0.01" gravity="0 0 0"/>
    
    <asset>
        <mesh name="base_mesh" file="base.stl" scale="0.001 0.001 0.001"/>
        <mesh name="motor110_mesh" file="motor110.stl" scale="0.001 0.001 0.001"/>
        <mesh name="motor70_mesh" file="motor70.stl" scale="0.001 0.001 0.001"/>
        <mesh name="link2_mesh" file="link2.stl" scale="0.001 0.001 0.001"/>
        <mesh name="link3_mesh" file="link3.stl" scale="0.001 0.001 0.001"/>
    </asset>

    <asset>
        <texture name="grid" type="2d" builtin="checker" rgb1=".1 .2 .3"
         rgb2=".2 .3 .4" width="300" height="300" mark="none"/>
        <material name="grid" texture="grid" texrepeat="1 1"
         texuniform="true" reflectance=".2"/>
      </asset>
    
    <worldbody>

        <!-- Ground plane -->
        <light name="light" pos="0 0 20"/>
        <geom name="ground" type="plane" pos="0 0 0" size="5 5 .1" material="grid"/>

        <!-- Robot Base -->
        <body name="base" pos="0 0 0">
            <geom type="capsule" fromto="0 0 0  0.5 0 0" size="0.006" rgba="1 0 0 1"/>
            <geom type="capsule" fromto="0 0 0  0 0.5 0" size="0.006" rgba="0 1 0 1"/>
            <geom type="capsule" fromto="0 0 0  0 0 0.5" size="0.006" rgba="0 0 1 1"/>
            <geom type="mesh" mesh="base_mesh" rgba="0.8 0.8 0.8 1" euler="0 0 3.1416"/>

            <!-- Link 1 -->
            <body name="link1" pos="-0.00000361 -0.00000271 0.0383" euler="0 0 0">
                <joint name="joint1" type="hinge" axis="0 0 1" limited="true" range="-3.1416 3.1416"/>
                <geom type="mesh" mesh="motor110_mesh" rgba="0.8 0.8 0.8 1" pos="0 0 0.074" euler = "0 0 0"/>
                
                <!-- Link 2 -->
                <body name="link2" pos="0 0.06 0.074" euler="1.5708 0 -0.5236"> <!-- initial rotation -30deg-->
                    <joint name="joint2" type="hinge" axis="0 0 1" limited="true" range="-3.1416 3.1416"/>
                    <geom type="mesh" mesh="motor110_mesh" rgba="0.8 0.8 0.8 1" pos="0 0 -0.08" euler = "0 3.1416 0"/>
                    <geom type="mesh" mesh="link2_mesh" rgba="0.8 0.8 0.8 1" pos="0 0.36 -0.08" euler = "0 0 0"/>
                    <geom type="mesh" mesh="motor110_mesh" rgba="0.8 0.8 0.8 1" pos="0 0.425 -0.08" euler = "3.1416 0 0"/>

                    <!-- Link 3 -->
                    <body name="link3" pos="0 0.425 0" euler="0 0 -0.5236"> <!-- initial rotation -30deg-->
                        <joint name="joint3" type="hinge" axis="0 0 1" limited="true" range="-3.1416 3.1416"/>
                        <geom type="mesh" mesh="motor110_mesh" rgba="0.8 0.8 0.8 1" pos="0 0 0.06" euler = "1.5708 0 3.1416"/>
                        
                        <!-- Link 4 -->
                        <body name="link4" pos="0 0.074 0.06" euler="-1.5708 0 0">
                            <joint name="joint4" type="hinge" axis="0 0 1" limited="true" range="-3.1416 3.1416"/>
                            <geom type="mesh" mesh="link3_mesh" rgba="0.8 0.8 0.8 1" pos="0 0 -0.015" euler = "-1.5708 0 0"/>
                            <geom type="mesh" mesh="motor70_mesh" rgba="0.8 0.8 0.8 1" pos="0 0 0.327" euler = "1.5708 3.1416 0"/>

                            <!-- Link 5 -->
                            <body name="link5" pos="0 0.04 0.327" euler="-1.5708 0 0.5236"> <!-- initial rotation 30deg-->
                                <joint name="joint5" type="hinge" axis="0 0 1" limited="true" range="-3.1416 3.1416"/>
                                <geom type="mesh" mesh="motor70_mesh" rgba="0.8 0.8 0.8 1" pos="0 0 0.047" euler = "1.5708 0 0"/>

                                <!-- Link 6 -->
                                <body name="link6" pos="0 -0.04 0.046" euler="1.5708 0 -1.5708"> <!-- initial rotation 90deg--> 
                                    <joint name="joint6" type="hinge" axis="0 0 1" limited="true" range="-3.1416 3.1416"/>
                                    <geom type="mesh" mesh="motor70_mesh" rgba="0.8 0.8 0.8 1" pos="0 0 0.045" euler = "1.5708 3.1416 0"/>
                                    <geom type="sphere" size="0.02" rgba="1 0 0 1"/>

                                    <!-- Link 7 -->
                                    <body name="link7" pos="0 0.0375 0.046" euler="-1.5708 0 0">
                                        <joint name="joint7" type="hinge" axis="0 0 1" limited="true" range="-3.1416 3.1416"/>
                                        <body name="ee" pos="0 0 0.0175">
                                            <geom type="capsule" fromto="0 0 0  0.05 0 0" size="0.005" rgba="1 0 0 1"/>
                                            <geom type="capsule" fromto="0 0 0  0 0.05 0" size="0.005" rgba="0 1 0 1"/>
                                            <geom type="capsule" fromto="0 0 0  0 0 0.05" size="0.005" rgba="0 0 1 1"/>
                                        </body>

                                    </body>
                                </body>
                            </body>
                        </body>
                    </body>
                </body>
            </body>

        </body>

    </worldbody>

    <sensor>
        <framepos name="ee_pos" objtype="body" objname="ee"/>
        <framequat name="ee_quat" objtype="body" objname="ee"/>
    </sensor>

</mujoco>
